Workbook

Sheet Summary
A1: VLM Industry Project Repository — Executive Summary
A2: 100 industry-validated Vision Language Model project ideas across 25 industries
A4: Projects by Industry | D4: Projects by Difficulty Level
A5: Category | B5: Project Count | D5: Category | E5: Project Count
A6: Aerospace | B6: =COUNTIF('VLM Projects'!$C$2:$C$101,A6) -> 4 | D6: Beginner | E6: =COUNTIF('VLM Projects'!$H$2:$H$101,D6) -> 20
A7: Agriculture | B7: =COUNTIF('VLM Projects'!$C$2:$C$101,A7) -> 4 | D7: Intermediate | E7: =COUNTIF('VLM Projects'!$H$2:$H$101,D7) -> 20
A8: Automotive | B8: =COUNTIF('VLM Projects'!$C$2:$C$101,A8) -> 4 | D8: Advanced | E8: =COUNTIF('VLM Projects'!$H$2:$H$101,D8) -> 30
A9: Banking & Finance | B9: =COUNTIF('VLM Projects'!$C$2:$C$101,A9) -> 4 | D9: Enterprise/Research | E9: =COUNTIF('VLM Projects'!$H$2:$H$101,D9) -> 30
A10: Construction | B10: =COUNTIF('VLM Projects'!$C$2:$C$101,A10) -> 4
A11: Cybersecurity | B11: =COUNTIF('VLM Projects'!$C$2:$C$101,A11) -> 4 | D11: Total | E11: =SUM(E6:E9) -> 100
A12: Defense | B12: =COUNTIF('VLM Projects'!$C$2:$C$101,A12) -> 4
A13: Education | B13: =COUNTIF('VLM Projects'!$C$2:$C$101,A13) -> 4 | D13: Projects by Recommended VLM
A14: Energy & Utilities | B14: =COUNTIF('VLM Projects'!$C$2:$C$101,A14) -> 4 | D14: Category | E14: Project Count
A15: Environmental & Climate | B15: =COUNTIF('VLM Projects'!$C$2:$C$101,A15) -> 4 | D15: CLIP | E15: =COUNTIF('VLM Projects'!$J$2:$J$101,D15) -> 4
A16: Government & Public Sector | B16: =COUNTIF('VLM Projects'!$C$2:$C$101,A16) -> 4 | D16: Florence-2 | E16: =COUNTIF('VLM Projects'!$J$2:$J$101,D16) -> 16
A17: Healthcare | B17: =COUNTIF('VLM Projects'!$C$2:$C$101,A17) -> 4 | D17: GPT-4o | E17: =COUNTIF('VLM Projects'!$J$2:$J$101,D17) -> 8
A18: Hospitality & Travel | B18: =COUNTIF('VLM Projects'!$C$2:$C$101,A18) -> 4 | D18: Gemini | E18: =COUNTIF('VLM Projects'!$J$2:$J$101,D18) -> 52
A19: Insurance | B19: =COUNTIF('VLM Projects'!$C$2:$C$101,A19) -> 4 | D19: Qwen2.5-VL | E19: =COUNTIF('VLM Projects'!$J$2:$J$101,D19) -> 20
A20: Legal Tech | B20: =COUNTIF('VLM Projects'!$C$2:$C$101,A20) -> 4
A21: Logistics & Supply Chain | B21: =COUNTIF('VLM Projects'!$C$2:$C$101,A21) -> 4 | D21: Total | E21: =SUM(E15:E19) -> 100
A22: Manufacturing | B22: =COUNTIF('VLM Projects'!$C$2:$C$101,A22) -> 4
A23: Media & Entertainment | B23: =COUNTIF('VLM Projects'!$C$2:$C$101,A23) -> 4 | D23: Projects by Resume Value Score
A24: Mining & Natural Resources | B24: =COUNTIF('VLM Projects'!$C$2:$C$101,A24) -> 4 | D24: Category | E24: Project Count
A25: Real Estate | B25: =COUNTIF('VLM Projects'!$C$2:$C$101,A25) -> 4 | D25: 1 | E25: =COUNTIF('VLM Projects'!$AS$2:$AS$101,D25) -> 0
A26: Retail & E-commerce | B26: =COUNTIF('VLM Projects'!$C$2:$C$101,A26) -> 4 | D26: 2 | E26: =COUNTIF('VLM Projects'!$AS$2:$AS$101,D26) -> 0
A27: Robotics | B27: =COUNTIF('VLM Projects'!$C$2:$C$101,A27) -> 4 | D27: 3 | E27: =COUNTIF('VLM Projects'!$AS$2:$AS$101,D27) -> 0
A28: Smart Cities | B28: =COUNTIF('VLM Projects'!$C$2:$C$101,A28) -> 4 | D28: 4 | E28: =COUNTIF('VLM Projects'!$AS$2:$AS$101,D28) -> 8
A29: Sports Analytics | B29: =COUNTIF('VLM Projects'!$C$2:$C$101,A29) -> 4 | D29: 5 | E29: =COUNTIF('VLM Projects'!$AS$2:$AS$101,D29) -> 11
A30: Telecommunications | B30: =COUNTIF('VLM Projects'!$C$2:$C$101,A30) -> 4 | D30: 6 | E30: =COUNTIF('VLM Projects'!$AS$2:$AS$101,D30) -> 14
D31: 7 | E31: =COUNTIF('VLM Projects'!$AS$2:$AS$101,D31) -> 18
A32: Total | B32: =SUM(B6:B30) -> 100 | D32: 8 | E32: =COUNTIF('VLM Projects'!$AS$2:$AS$101,D32) -> 23
D33: 9 | E33: =COUNTIF('VLM Projects'!$AS$2:$AS$101,D33) -> 18
D34: 10 | E34: =COUNTIF('VLM Projects'!$AS$2:$AS$101,D34) -> 8
A35: Projects by Startup Potential Score
A36: Category | B36: Project Count | D36: Average Score | E36: =AVERAGE('VLM Projects'!$AS$2:$AS$101) -> 7.23
A37: 1 | B37: =COUNTIF('VLM Projects'!$AU$2:$AU$101,A37) -> 0
A38: 2 | B38: =COUNTIF('VLM Projects'!$AU$2:$AU$101,A38) -> 0
A39: 3 | B39: =COUNTIF('VLM Projects'!$AU$2:$AU$101,A39) -> 8
A40: 4 | B40: =COUNTIF('VLM Projects'!$AU$2:$AU$101,A40) -> 8
A41: 5 | B41: =COUNTIF('VLM Projects'!$AU$2:$AU$101,A41) -> 9
...

Sheet VLM Projects
A1: Project ID | B1: Project Title | C1: Industry | D1: Industry Problem | E1: Existing Manual Process | F1: AI Opportunity | G1: Business Impact | H1: Difficulty Level | I1: Estimated Development Time | J1: Recommended VLM | K1: Alternative Models | L1: Why this model? | M1: Dataset Recommendation | N1: Dataset Source | O1: Data Type | P1: Expected Dataset Size | Q1: Open Dataset Available? (Yes/No) | R1: APIs Required | S1: Hardware Requirement | T1: Cloud Deployment Option | U1: Tech Stack | V1: Frontend | W1: Backend | X1: Database | Y1: Authentication | Z1: AI Framework | AA1: Vector Database | AB1: RAG Required? | AC1: Agentic AI Extension | AD1: Multi-Agent Possibility | AE1: OCR Required? | AF1: Speech Required? | AG1: Video Understanding? | AH1: Image Generation? | AI1: Report Generation? | AJ1: Dashboard Needed? | AK1: User Roles | AL1: Key Features | AM1: Advanced Features | AN1: Enterprise Features | AO1: Security Considerations | AP1: Compliance Requirements | AQ1: Evaluation Metrics | AR1: Deployment Difficulty | AS1: Resume Value (1-10) | AT1: Interview Probability (1-10) | AU1: Startup Potential (1-10) | AV1: Enterprise Adoption (1-10) | AW1: Research Potential (1-10) | AX1: Monetization Strategy
A2: VLM-001 | B2: MedScan Radiology Triage Copilot | C2: Healthcare | D2: Radiologists face multi-hour backlogs reading X-rays/CTs, delaying critical diagnoses. | E2: Radiologists manually review every scan in FIFO order regardless of urgency. | F2: VLM flags critical findings (e.g., pneumothorax, hemorrhage) and re-prioritizes the reading queue in real time. | G2: Cuts time-to-diagnosis for critical cases from hours to minutes; reduces missed critical findings. | H2: Beginner | I2: 2-4 weeks | J2: Qwen2.5-VL | K2: Florence-2, GPT-4o | L2: Best-in-class dense OCR and layout understanding for handwritten/printed clinical documents, with strong structured-field extraction. | M2: MIMIC-CXR + NIH ChestX-ray14 | N2: PhysioNet / NIH Clinical Center | O2: Medical images + radiology reports | P2: ~370K images | Q2: Yes | R2: Qwen2.5-VL API, cloud storage API, domain system integration API | S2: Single GPU (e.g., NVIDIA T4/RTX 3060) or hosted API only | T2: AWS/GCP/Azure free-tier or serverless functions | U2: Python microservices + React frontend + containerized inference (Docker/Kubernetes) | V2: React + TypeScript (Tailwind CSS) | W2: FastAPI (Python) | X2: PostgreSQL + S3-compatible object storage | Y2: OAuth2/JWT | Z2: Hugging Face Transformers + LangChain | AA2: Pinecone / Weaviate (embedding-based search index) | AB2: Yes | AC2: Extend with an autonomous clinical-workflow agent that routes flagged cases, drafts follow-up orders, and schedules specialist review. | AD2: No — single-agent pipeline is sufficient at current scope; multi-agent orchestration is a future extension. | AE2: Yes | AF2: No | AG2: No | AH2: No | AI2: Yes | AJ2: Yes | AK2: Radiologist, Technologist, Hospital Admin, Referring Physician | AL2: DICOM viewer, critical-finding flagging, auto-generated draft report, priority queue | AM2: Longitudinal comparison to prior scans, uncertainty calibration, sub-specialist routing | AN2: PACS/RIS integration, audit trail, multi-site federated learning, radiologist sign-off workflow | AO2: PHI de-identification, encryption at rest/in transit, role-based clinical access control, audit logging | AP2: HIPAA, FDA SaMD Class II, HL7/DICOM | AQ2: AUROC, sensitivity/specificity, report concordance (BLEU/ROUGE vs radiologist), turnaround time | AR2: Low | AS2: 6 | AT2: 6 | AU2: 3 | AV2: 4 | AW2: 1 | AX2: Per-scan SaaS licensing to hospital networks + enterprise PACS integration fee
A3: VLM-002 | B3: Surgical Video Skill Assessment Platform | C3: Healthcare | D3: Surgical training programs lack scalable, objective ways to assess trainee technique across thousands of recorded procedures. | E3: Attending surgeons manually review recorded footage and score trainees subjectively. | F3: VLM analyzes surgical video to score technique, detect critical errors, and generate structured feedback. | G3: Standardizes surgical competency assessment and shortens certification review cycles by 60%. | H3: Beginner | I3: 2-4 weeks | J3: Gemini | K3: GPT-4o, Qwen2.5-VL | L3: Native long-context multi-frame video reasoning lets it track temporal patterns across extended footage without heavy pre-processing. | M3: Cholec80 + JIGSAWS | N3: Public surgical video datasets | O3: Endoscopic/surgical video | P3: ~150 hours video | Q3: Yes | R3: Gemini API, cloud storage API, domain system integration API | S3: Single GPU (e.g., NVIDIA T4/RTX 3060) or hosted API only | T3: AWS/GCP/Azure free-tier or serverless functions | U3: Python microservices + React frontend + containerized inference (Docker/Kubernetes) | V3: React + TypeScript (Tailwind CSS) | W3: FastAPI (Python) | X3: PostgreSQL + S3-compatible object storage | Y3: OAuth2/JWT | Z3: Hugging Face Transformers + LangChain | AA3: N/A (real-time inference only) | AB3: No | AC3: Extend with an agent that correlates detections across time/cameras, triggers automated alerts, and files incident reports without human initiation. | AD3: No — single-agent pipeline is sufficient at current scope; multi-agent orchestration is a future extension. | AE3: No | AF3: No | AG3: Yes | AH3: No | AI3: Yes | AJ3: Yes | AK3: Surgeon, Trainee, Program Director, Credentialing Board | AL3: Frame-level instrument tracking, skill scoring rubric, timestamped feedback | AM3: Phase recognition, complication risk prediction, peer benchmarking | AN3: Credentialing board integration, multi-institution leaderboards, tamper-proof audit logs | AO3: PHI de-identification, encryption at rest/in transit, role-based clinical access control, audit logging | AP3: HIPAA, ACGME accreditation standards | AQ3: Inter-rater reliability vs expert scores, error-detection recall, F1 on phase segmentation | AR3: Low | AS3: 4 | AT3: 6 | AU3: 3 | AV3: 3 | AW3: 2 | AX3: Per-seat subscription to teaching hospitals + certification body licensing
A4: VLM-003 | B4: Home-Care Wound Monitoring Assistant | C4: Healthcare | D4: Chronic wound and post-surgical patients recovering at home lack consistent clinical monitoring, risking undetected infection. | E4: Patients or home-care nurses take phone photos and describe wounds verbally during infrequent visits. | F4: VLM analyzes patient-submitted wound photos for infection signs, healing trajectory, and escalation triggers. | G4: Reduces preventable ER readmissions from wound complications and cuts nurse home-visit load. | H4: Intermediate | I4: 1-2 months | J4: GPT-4o | K4: Gemini, Qwen2.5-VL | L4: Strong agentic function-calling and multimodal reasoning make it best suited to orchestrate multi-step, tool-using workflows. | M4: Custom wound image + clinician annotation set | N4: Partner dermatology/wound clinics | O4: Smartphone images + clinical notes | P4: ~20K annotated images | Q4: No | R4: GPT-4o API, cloud storage API, domain system integration API | S4: Single A10/A100 GPU workstation | T4: AWS SageMaker / GCP Vertex AI / Azure ML (single-node) | U4: Python microservices + React frontend + containerized inference (Docker/Kubernetes) | V4: React + TypeScript (Tailwind CSS) | W4: FastAPI (Python) | X4: PostgreSQL + S3-compatible object storage | Y4: OAuth2/JWT | Z4: Hugging Face Transformers + LangChain | AA4: Pinecone / Weaviate (embedding-based search index) | AB4: Yes | AC4: Extend into a fully autonomous multi-step agent that plans, executes, and verifies physical/digital tasks with minimal human supervision. | AD4: No — single-agent pipeline is sufficient at current scope; multi-agent orchestration is a future extension. | AE4: No | AF4: No | AG4: No | AH4: No | AI4: Yes | AJ4: Yes | AK4: Patient, Home-Care Nurse, Physician, Care Coordinator | AL4: Photo capture guide, healing-stage classifier, infection risk score | AM4: Longitudinal healing curve, personalized care plan generation, nurse triage chat | AN4: EHR integration, remote monitoring billing codes, clinician dashboard with alerting | AO4: PHI de-identification, encryption at rest/in transit, role-based clinical access control, audit logging | AP4: HIPAA, RPM/CPT billing compliance | AQ4: Sensitivity for infection detection, healing-stage classification accuracy, alert precision | AR4: Medium | AS4: 6 | AT4: 5 | AU4: 5 | AV4: 4 | AW4: 4 | AX4: Remote Patient Monitoring (RPM) reimbursement billing + per-patient SaaS fee
A5: VLM-004 | B5: Pharmacy Prescription Verification Vision System | C5: Healthcare | D5: Pharmacists spend significant time manually cross-checking handwritten and printed prescriptions against pharmacy records, risking dispensing errors. | E5: Pharmacy staff manually read and key in prescription details, then double-check by hand. | F5: VLM reads handwritten/printed prescriptions, cross-verifies dosage against drug interaction databases, and flags anomalies. | G5: Reduces dispensing errors and manual data-entry time by a majority in high-volume pharmacies. | H5: Intermediate | I5: 1-2 months | J5: Qwen2.5-VL | K5: Florence-2, GPT-4o | L5: Best-in-class dense OCR and layout understanding for handwritten/printed clinical documents, with strong structured-field extraction. | M5: Custom prescription image dataset | N5: Partner pharmacy chains + synthetic generation | O5: Scanned/photographed prescriptions | P5: ~50K prescriptions | Q5: No | R5: Qwen2.5-VL API, cloud storage API, domain system integration API | S5: Single A10/A100 GPU workstation | T5: AWS SageMaker / GCP Vertex AI / Azure ML (single-node) | U5: Python microservices + React frontend + containerized inference (Docker/Kubernetes) | V5: React + TypeScript (Tailwind CSS) | W5: FastAPI (Python) | X5: PostgreSQL + S3-compatible object storage | Y5: OAuth2/JWT | Z5: Hugging Face Transformers + LangChain | AA5: Pinecone / Weaviate (embedding-based search index) | AB5: Yes | AC5: Extend with an autonomous clinical-workflow agent that routes flagged cases, drafts follow-up orders, and schedules specialist review. | AD5: No — single-agent pipeline is sufficient at current scope; multi-agent orchestration is a future extension. | AE5: Yes | AF5: No | AG5: No | AH5: No | AI5: Yes | AJ5: Yes | AK5: Pharmacist, Pharmacy Technician, Compliance Officer | AL5: Handwriting OCR, drug-name normalization, dosage sanity checks | AM5: Drug interaction reasoning, insurance formulary matching, refill prediction | AN5: Pharmacy management system integration, DEA compliance logging, tamper detection | AO5: PHI de-identification, encryption at rest/in transit, role-based clinical access control, audit logging | AP5: HIPAA, DEA regulations, FDA drug labeling standards | AQ5: Character/word error rate, drug-name accuracy, error-flag precision/recall | AR5: Medium | AS5: 5 | AT5: 5 | AU5: 6 | AV5: 4 | AW5: 3 | AX5: Per-location SaaS fee to pharmacy chains + transaction-based pricing
A6: VLM-005 | B6: Loan Document Fraud Detection Suite | C6: Banking & Finance | D6: Banks lose billions annually to fraudulent loan applications using forged pay stubs, bank statements, and IDs. | E6: Underwriters manually eyeball scanned documents for inconsistencies and font mismatches. | F6: VLM cross-validates document layout, font consistency, and embedded metadata to flag forged financial documents. | G6: Reduces fraud losses and manual underwriting review time significantly across loan portfolios. | H6: Advanced | I6: 3-5 months | J6: Qwen2.5-VL | K6: Florence-2, GPT-4o | L6: Superior document-grounding and table/field extraction accuracy needed for financial/legal/regulatory documents. | M6: Custom synthetic + real forged document corpus | N6: Partner banks + synthetic forgery generation | O6: Scanned financial documents | P6: ~80K documents | Q6: No | R6: Qwen2.5-VL API, cloud storage API, payment/ERP integration API | S6: Multi-GPU cluster (A100/H100) for fine-tuning + low-latency inference | T6: AWS/GCP/Azure Kubernetes-based multi-region deployment | U6: Python microservices + React frontend + containerized inference (Docker/Kubernetes) | V6: React + TypeScript (Tailwind CSS) | W6: FastAPI (Python) + microservices with message queue (Kafka/RabbitMQ) | X6: PostgreSQL + S3-compatible object storage | Y6: SSO/SAML + RBAC + OAuth2 | Z6: Hugging Face Transformers + LangChain/LlamaIndex + Ray/Kubeflow for scaling | AA6: Pinecone / Weaviate (embedding-based search index) | AB6: Yes | AC6: Extend with an autonomous compliance agent that files exceptions, requests missing documents, and escalates high-risk cases automatically. | AD6: Yes — specialist sub-agents (extraction, verification, routing) can coordinate via an orchestrator agent. | AE6: Yes | AF6: No | AG6: No | AH6: No | AI6: Yes | AJ6: Yes | AK6: Underwriter, Fraud Analyst, Compliance Officer, Loan Applicant | AL6: Document authenticity scoring, field extraction, tamper heatmap | AM6: Cross-document consistency graph, applicant history correlation, explainable fraud reasoning | AN6: Core banking integration, SOC2 audit logging, regulator-ready explainability reports | AO6: PCI-DSS scope minimization, encryption at rest/in transit, role-based access control, immutable audit trail | AP6: SOX, GLBA, FCRA, AML/KYC regulations | AQ6: Precision/recall on labeled fraud set, false-positive rate, review-time reduction | AR6: High | AS6: 7 | AT6: 9 | AU6: 8 | AV6: 6 | AW6: 7 | AX6: Per-transaction pricing to banks + enterprise annual license
A7: VLM-006 | B7: Check & Remittance Image Processing Engine | C7: Banking & Finance | D7: Regional banks still process large volumes of paper checks and remittance slips requiring manual data entry. | E7: Back-office staff manually key in amounts, account numbers, and MICR data from scanned checks. | F7: VLM extracts MICR line, courtesy/legal amount, and signature presence with cross-field validation. | G7: Cuts check-processing labor costs and same-day clearing errors substantially. | H7: Advanced | I7: 3-5 months | J7: Qwen2.5-VL | K7: Florence-2, GPT-4o | L7: Superior document-grounding and table/field extraction accuracy needed for financial/legal/regulatory documents. | M7: CROHME + custom check scans | N7: Public handwriting datasets + bank partners | O7: Scanned checks/remittance slips | P7: ~100K check images | Q7: Partial | R7: Qwen2.5-VL API, cloud storage API, payment/ERP integration API | S7: Multi-GPU cluster (A100/H100) for fine-tuning + low-latency inference | T7: AWS/GCP/Azure Kubernetes-based multi-region deployment | U7: Python microservices + React frontend + containerized inference (Docker/Kubernetes) | V7: React + TypeScript (Tailwind CSS) | W7: FastAPI (Python) + microservices with message queue (Kafka/RabbitMQ) | X7: PostgreSQL + S3-compatible object storage | Y7: SSO/SAML + RBAC + OAuth2 | Z7: Hugging Face Transformers + LangChain/LlamaIndex + Ray/Kubeflow for scaling | AA7: Pinecone / Weaviate (embedding-based search index) | AB7: Yes | AC7: Extend with an autonomous compliance agent that files exceptions, requests missing documents, and escalates high-risk cases automatically. | AD7: Yes — specialist sub-agents (extraction, verification, routing) can coordinate via an orchestrator agent. | AE7: Yes | AF7: No | AG7: No | AH7: No | AI7: Yes | AJ7: Yes | AK7: Bank Teller, Back-Office Clerk, Compliance Officer | AL7: MICR extraction, amount reconciliation, signature verification | AM7: Courtesy/legal amount mismatch resolution, duplicate check detection | AN7: Core banking API integration, Reg CC compliance logging, multi-bank clearinghouse support | AO7: PCI-DSS scope minimization, encryption at rest/in transit, role-based access control, immutable audit trail | AP7: Reg CC, Check 21 Act, SOX | AQ7: Field extraction accuracy, amount-match rate, exception-handling turnaround | AR7: High | AS7: 8 | AT7: 8 | AU7: 8 | AV7: 8 | AW7: 7 | AX7: Per-item processing fee to regional/community banks
A8: VLM-007 | B8: Trading Floor Multi-Screen Compliance Monitor | C8: Banking & Finance | D8: Compliance teams struggle to detect risky trader behavior (e.g., unauthorized screens, phone use) across large trading floors. | E8: Compliance officers do periodic manual walk-throughs and spot-check camera footage. | F8: VLM analyzes desk camera feeds to detect policy violations like unauthorized devices or screen-sharing. | G8: Reduces regulatory violation incidents and manual surveillance labor on trading floors. | H8: Advanced | I8: 3-5 months | J8: Gemini | K8: GPT-4o, Qwen2.5-VL | L8: Native long-context multi-frame video reasoning lets it track temporal patterns across extended footage without heavy pre-processing. | M8: Custom trading-floor surveillance footage | N8: Partner investment banks (privacy-controlled) | O8: CCTV video | P8: ~5K hours video | Q8: No | R8: Gemini API, cloud storage API, payment/ERP integration API | S8: Multi-GPU cluster (A100/H100) for fine-tuning + low-latency inference | T8: AWS/GCP/Azure Kubernetes-based multi-region deployment | U8: Python microservices + React frontend + containerized inference (Docker/Kubernetes) | V8: React + TypeScript (Tailwind CSS) | W8: FastAPI (Python) + microservices with message queue (Kafka/RabbitMQ) | X8: PostgreSQL + S3-compatible object storage | Y8: SSO/SAML + RBAC + OAuth2 | Z8: Hugging Face Transformers + LangChain/LlamaIndex + Ray/Kubeflow for scaling | AA8: N/A (real-time inference only) | AB8: No | AC8: Extend with an agent that correlates detections across time/cameras, triggers automated alerts, and files incident reports without human initiation. | AD8: Yes — specialist sub-agents (extraction, verification, routing) can coordinate via an orchestrator agent. | AE8: No | AF8: No | AG8: Yes | AH8: No | AI8: Yes | AJ8: Yes | AK8: Compliance Officer, Trader, Risk Manager | AL8: Object/device detection, policy-violation alerting, incident logging | AM8: Behavioral anomaly detection, cross-camera person tracking, risk scoring | AN8: SIEM integration, regulator audit export, privacy-preserving on-prem deployment | AO8: PCI-DSS scope minimization, encryption at rest/in transit, role-based access control, immutable audit trail | AP8: MiFID II, SEC/FINRA surveillance rules, employee privacy law | AQ8: Detection precision/recall, false-alarm rate, incident resolution time | AR8: High | AS8: 7 | AT8: 7 | AU8: 8 | AV8: 7 | AW8: 7 | AX8: Enterprise annual license to investment banks and trading firms
A9: VLM-008 | B9: Invoice-to-Ledger Reconciliation Copilot | C9: Banking & Finance | D9: Corporate finance teams spend excessive hours manually matching vendor invoices to purchase orders and ledger entries. | E9: AP clerks manually compare invoice PDFs/images against ERP purchase order records line by line. | F9: VLM reads invoices, matches line items to POs, and auto-flags discrepancies for approval routing. | G9: Speeds up close cycles and cuts manual reconciliation effort dramatically. | H9: Enterprise/Research | I9: 6-12+ months | J9: Qwen2.5-VL | K9: Florence-2, GPT-4o | L9: Superior document-grounding and table/field extraction accuracy needed for financial/legal/regulatory documents. | M9: SROIE + custom invoice corpus | N9: SROIE (ICDAR) + enterprise partners | O9: Scanned/PDF invoices | P9: ~40K invoices | Q9: Yes | R9: Qwen2.5-VL API, cloud storage API, payment/ERP integration API | S9: Multi-node H100 cluster with on-prem/edge hybrid, redundant failover infrastructure | T9: Enterprise private cloud / hybrid on-prem with data-residency controls | U9: Python microservices + React frontend + containerized inference (Docker/Kubernetes) | V9: React + TypeScript (Tailwind CSS) with role-based enterprise UI | W9: FastAPI (Python) + microservices with message queue (Kafka/RabbitMQ) | X9: PostgreSQL + S3-compatible object storage | Y9: SSO/SAML + RBAC + OAuth2 | Z9: Hugging Face Transformers + LangChain/LlamaIndex + Ray/Kubeflow for scaling | AA9: Pinecone / Weaviate (embedding-based search index) | AB9: Yes | AC9: Extend with an autonomous compliance agent that files exceptions, requests missing documents, and escalates high-risk cases automatically. | AD9: Yes — specialist sub-agents (extraction, verification, routing) can coordinate via an orchestrator agent. | AE9: Yes | AF9: No | AG9: No | AH9: No | AI9: Yes | AJ9: Yes | AK9: AP Clerk, Controller, Vendor, Auditor | AL9: Line-item extraction, PO matching, discrepancy flagging | AM9: Multi-currency normalization, vendor risk scoring, duplicate invoice detection | AN9: ERP (SAP/Oracle) integration, SOX-compliant audit trail, approval workflow engine | AO9: PCI-DSS scope minimization, encryption at rest/in transit, role-based access control, immutable audit trail | AP9: SOX, IFRS/GAAP reporting standards | AQ9: Field extraction F1, matching accuracy, days-to-close reduction | AR9: Very High | AS9: 8 | AT9: 8 | AU9: 8 | AV9: 9 | AW9: 9 | AX9: Per-invoice processing fee + tiered enterprise ERP add-on
A10: VLM-009 | B10: Auto Claims Damage Estimator | C10: Insurance | D10: Insurers face slow, inconsistent manual vehicle damage assessments that delay claim payouts and invite disputes. | E10: Adjusters physically inspect vehicles or review photos manually to estimate repair costs. | F10: VLM analyzes uploaded vehicle photos to identify damage location/severity and estimate repair cost ranges. | G10: Shortens claim cycle time from days to minutes and reduces adjuster travel costs. | H10: Enterprise/Research | I10: 6-12+ months | J10: Gemini | K10: GPT-4o, Qwen2.5-VL | L10: Native long-context multi-frame video reasoning lets it track temporal patterns across extended footage without heavy pre-processing. | M10: CarDD + custom claim photo set | N10: CarDD dataset + insurer partners | O10: Smartphone vehicle photos | P10: ~15K annotated images | Q10: Yes | R10: Gemini API, cloud storage API, payment/ERP integration API | S10: Multi-node H100 cluster with on-prem/edge hybrid, redundant failover infrastructure | T10: Enterprise private cloud / hybrid on-prem with data-residency controls | U10: Python microservices + React frontend + containerized inference (Docker/Kubernetes) | V10: React + TypeScript (Tailwind CSS) with role-based enterprise UI | W10: FastAPI (Python) + microservices with message queue (Kafka/RabbitMQ) | X10: PostgreSQL + S3-compatible object storage | Y10: SSO/SAML + RBAC + OAuth2 | Z10: Hugging Face Transformers + LangChain/LlamaIndex + Ray/Kubeflow for scaling | AA10: N/A (real-time inference only) | AB10: No | AC10: Extend with an agent that correlates detections across time/cameras, triggers automated alerts, and files incident reports without human initiation. | AD10: Yes — specialist sub-agents (extraction, verification, routing) can coordinate via an orchestrator agent. | AE10: No | AF10: No | AG10: Yes | AH10: No | AI10: Yes | AJ10: Yes | AK10: Policyholder, Claims Adjuster, Repair Shop, Fraud Investigator | AL10: Damage localization, severity scoring, cost estimate generator | AM10: Multi-angle 3D damage reconstruction, prior-claim fraud cross-check | AN10: Claims management system integration, adjuster override workflow, state DOI reporting | AO10: PII protection, encryption at rest/in transit, role-based access control, tamper-evident audit logging | AP10: State insurance DOI regulations, NAIC model laws | AQ10: Damage-severity classification accuracy, cost-estimate MAE vs actual repair invoice | AR10: Very High | AS10: 10 | AT10: 9 | AU10: 9 | AV10: 9 | AW10: 8 | AX10: Per-claim processing fee licensed to insurance carriers
A11: VLM-010 | B11: Property Inspection Risk Scoring Platform | C11: Insurance | D11: Underwriters cannot economically inspect every property for roof condition, fire hazards, or code violations before issuing policies. | E11: Human inspectors visit properties or review drone/satellite photos manually to assess risk. | F11: VLM analyzes aerial/satellite and drone imagery to detect roof damage, vegetation risk, and structural hazards. | G11: Enables risk-based underwriting at scale and reduces inspection costs for insurers. | H11: Enterprise/Research | I11: 6-12+ months | J11: Gemini | K11: GPT-4o, Qwen2.5-VL | L11: Native long-context multi-frame video reasoning lets it track temporal patterns across extended footage without heavy pre-processing. | M11: xBD building damage dataset + aerial imagery | N11: xBD (public) + satellite providers | O11: Satellite/aerial/drone imagery | P11: ~30K property images | Q11: Yes | R11: Gemini API, cloud storage API, payment/ERP integration API | S11: Multi-node H100 cluster with on-prem/edge hybrid, redundant failover infrastructure | T11: Enterprise private cloud / hybrid on-prem with data-residency controls | U11: Python microservices + React frontend + containerized inference (Docker/Kubernetes) | V11: React + TypeScript (Tailwind CSS) with role-based enterprise UI | W11: FastAPI (Python) + microservices with message queue (Kafka/RabbitMQ) | X11: PostgreSQL + S3-compatible object storage | Y11: SSO/SAML + RBAC + OAuth2 | Z11: Hugging Face Transformers + LangChain/LlamaIndex + Ray/Kubeflow for scaling | AA11: N/A (real-time inference only) | AB11: No | AC11: Extend with an agent that correlates detections across time/cameras, triggers automated alerts, and files incident reports without human initiation. | AD11: Yes — specialist sub-agents (extraction, verification, routing) can coordinate via an orchestrator agent. | AE11: No | AF11: No | AG11: Yes | AH11: No | AI11: Yes | AJ11: Yes | AK11: Underwriter, Actuary, Property Owner, Reinsurer | AL11: Roof-condition classifier, hazard detection, risk score generation | AM11: Change detection over time, wildfire/flood exposure modeling | AN11: GIS integration, state regulatory rate-filing support, reinsurer reporting | AO11: PII protection, encryption at rest/in transit, role-based access control, tamper-evident audit logging | AP11: State insurance regulations, fair-housing/non-discrimination law | AQ11: Hazard detection precision/recall, risk-score correlation with actual claims | AR11: Very High | AS11: 9 | AT11: 8 | AU11: 9 | AV11: 9 | AW11: 8 | AX11: Per-property risk report fee + underwriting API subscription
A12: VLM-011 | B12: Health Insurance Prior-Authorization Document Reader | C12: Insurance | D12: Health insurers face huge backlogs manually reviewing clinical documents to approve or deny prior-authorization requests. | E12: Nurses/reviewers manually read faxed clinical notes and match against coverage criteria. | F12: VLM extracts clinical data from faxed/scanned documents and matches against payer policy criteria automatically. | G12: Cuts prior-auth turnaround from days to hours, improving patient care access. | H12: Beginner | I12: 2-4 weeks | J12: Qwen2.5-VL | K12: Florence-2, GPT-4o | L12: Best-in-class dense OCR and layout understanding for handwritten/printed clinical documents, with strong structured-field extraction. | M12: Custom clinical fax/document corpus | N12: Partner payers (de-identified) | O12: Faxed/scanned clinical documents | P12: ~60K documents | Q12: No | R12: Qwen2.5-VL API, cloud storage API, payment/ERP integration API | S12: Single GPU (e.g., NVIDIA T4/RTX 3060) or hosted API only | T12: AWS/GCP/Azure free-tier or serverless functions | U12: Python microservices + React frontend + containerized inference (Docker/Kubernetes) | V12: React + TypeScript (Tailwind CSS) | W12: FastAPI (Python) | X12: PostgreSQL + S3-compatible object storage | Y12: OAuth2/JWT | Z12: Hugging Face Transformers + LangChain | AA12: Pinecone / Weaviate (embedding-based search index) | AB12: Yes | AC12: Extend with an autonomous clinical-workflow agent that routes flagged cases, drafts follow-up orders, and schedules specialist review. | AD12: No — single-agent pipeline is sufficient at current scope; multi-agent orchestration is a future extension. | AE12: Yes | AF12: No | AG12: No | AH12: No | AI12: Yes | AJ12: Yes | AK12: Utilization Reviewer, Physician, Patient, Compliance Officer | AL12: Clinical entity extraction, policy criteria matcher, auto-approve/deny recommendation | AM12: Explainable denial reasoning, appeals-letter drafting assistant | AN12: Payer core system integration, HIPAA audit logging, appeals workflow | AO12: PII protection, encryption at rest/in transit, role-based access control, tamper-evident audit logging | AP12: HIPAA, ACA prior-authorization regulations, state insurance law | AQ12: Auto-decision accuracy vs human reviewer, turnaround-time reduction, appeal-overturn rate | AR12: Low | AS12: 4 | AT12: 5 | AU12: 4 | AV12: 2 | AW12: 2 | AX12: Per-request processing fee to health payers
A13: VLM-012 | B13: Catastrophe Response Aerial Damage Mapper | C13: Insurance | D13: After hurricanes/wildfires, insurers cannot rapidly assess widespread property damage across thousands of claims simultaneously. | E13: Adjusters are dispatched region by region over weeks to visually assess damage. | F13: VLM processes drone/satellite sweeps post-disaster to auto-classify damage severity across entire affected regions. | G13: Accelerates catastrophe claim payouts from weeks to days, improving policyholder outcomes and insurer cash-flow planning. | H13: Beginner | I13: 2-4 weeks | J13: Gemini | K13: GPT-4o, Qwen2.5-VL | L13: Native long-context multi-frame video reasoning lets it track temporal patterns across extended footage without heavy pre-processing. | M13: xBD + FEMA disaster imagery | N13: xBD (public), FEMA open data | O13: Post-disaster aerial imagery | P13: ~50K image pairs (pre/post) | Q13: Yes | R13: Gemini API, cloud storage API, payment/ERP integration API | S13: Single GPU (e.g., NVIDIA T4/RTX 3060) or hosted API only | T13: AWS/GCP/Azure free-tier or serverless functions | U13: Python microservices + React frontend + containerized inference (Docker/Kubernetes) | V13: React + TypeScript (Tailwind CSS) | W13: FastAPI (Python) | X13: PostgreSQL + S3-compatible object storage | Y13: OAuth2/JWT | Z13: Hugging Face Transformers + LangChain | AA13: N/A (real-time inference only) | AB13: No | AC13: Extend with an agent that correlates detections across time/cameras, triggers automated alerts, and files incident reports without human initiation. | AD13: No — single-agent pipeline is sufficient at current scope; multi-agent orchestration is a future extension. | AE13: No | AF13: No | AG13: Yes | AH13: No | AI13: Yes | AJ13: Yes | AK13: Claims Adjuster, Catastrophe Modeler, Policyholder, Regulator | AL13: Pre/post damage comparison, severity heatmaps, batch claim triage | AM13: Multi-peril model fusion (wind/flood/fire), automated payout tier recommendation | AN13: Catastrophe modeling platform integration, regulator disaster reporting, reinsurance treaty triggers | AO13: PII protection, encryption at rest/in transit, role-based access control, tamper-evident audit logging | AP13: State DOI catastrophe response mandates, NAIC guidelines | AQ13: Damage-tier classification accuracy vs ground truth, claim-processing time reduction | AR13: Low | AS13: 4 | AT13: 4 | AU13: 4 | AV13: 3 | AW13: 2 | AX13: Per-event enterprise licensing to insurers/reinsurers
... A101: VLM-100 | B101: Retail Store Network Equipment Rollout Verifier | C101: Telecommunications | D101: Carriers and retail-network operators struggle to verify correct multi-site rollout of signage, kiosks, and network equipment during large deployments. | E101: Field auditors manually visit each site to photograph and checklist-verify installed equipment against rollout specs. | F101: VLM analyzes site-submitted installation photos to auto-verify equipment placement, signage compliance, and branding accuracy against rollout specs. | G101: Speeds up large-scale multi-site rollouts and reduces costly re-visit rates for correction. | H101: Enterprise/Research | I101: 6-12+ months | J101: Florence-2 | K101: Qwen2.5-VL, CLIP | L101: Excellent fine-grained visual grounding and region-level defect localization, lightweight enough for edge/line deployment. | M101: Custom multi-site rollout imagery | N101: Carrier/retail rollout partners | O101: Site installation photos | P101: ~12K site images | Q101: No | R101: Florence-2 API, cloud storage API, domain system integration API | S101: Multi-node H100 cluster with on-prem/edge hybrid, redundant failover infrastructure | T101: Enterprise private cloud / hybrid on-prem with data-residency controls | U101: Python microservices + React frontend + containerized inference (Docker/Kubernetes) | V101: React + TypeScript (Tailwind CSS) with role-based enterprise UI | W101: FastAPI (Python) + microservices with message queue (Kafka/RabbitMQ) | X101: PostgreSQL + S3-compatible object storage | Y101: SSO/SAML + RBAC + OAuth2 | Z101: Hugging Face Transformers + LangChain/LlamaIndex + Ray/Kubeflow for scaling | AA101: N/A (real-time inference only) | AB101: No | AC101: Extend with an agent that auto-creates maintenance tickets, orders replacement parts, and schedules technician dispatch based on defect severity. | AD101: Yes — specialist sub-agents (extraction, verification, routing) can coordinate via an orchestrator agent. | AE101: No | AF101: No | AG101: No | AH101: No | AI101: Yes | AJ101: Yes | AK101: Field Installer, Rollout Program Manager, Brand Compliance Officer | AL101: Placement/signage compliance check, brand-standard verification, pass/fail scoring per site | AM101: Cross-site rollout-quality benchmarking, predictive re-visit risk scoring by installer crew | AN101: Rollout project-management system integration, multi-region program dashboard, vendor-performance scorecarding | AO101: Customer/network data protection, encryption at rest/in transit, role-based access control, network-change audit logging | AP101: Brand licensing/franchise compliance standards | AQ101: Compliance-verification accuracy, re-visit-rate reduction, rollout-time reduction | AR101: Very High | AS101: 8 | AT101: 8 | AU101: 9 | AV101: 10 | AW101: 8 | AX101: Per-site verification fee to carriers and retail network operators
